Workbook

Sheet README
A1: MTP-F26 Team C - Radio Team workbook
A2: Owner: Radio Team (Santiago, Andrian, Marcos). Version 0.1, 2026-10-03.
A4: Sheets
A5: Link Budget - AN5142 rows (course-corrected), one column per scenario S1-S12. This is the ANNEX 'Link Budget Analysis' artefact.
A6: Height Sweep - same budgets recomputed for antenna heights 0.5-1.5 m.
A7: Throughput - lines delivered in 120 s per radio/data rate; occupied bandwidth check for the 250 kHz 868 sub-band.
A8: Candidates - radio module shortlist with datasheet figures, gotchas and compliance notes.
A9: Regulatory - CNAF 2017 bands usable for a 2-minute continuous round.
A11: Legend
A12: Blue text = input you may change. Black = formula. Green = link to another sheet.
A13: Yellow fill = key assumption that must be replaced by a measurement (antenna gain in box, container loss, multipath, heights).
A14: Green fill = results.
... A24: 3. Replace every yellow assumption with a measured value (tests T2 bench PER, T4/T5 range, T13 spectrum).

Sheet Link Budget
A1: MTP-F26 Team C - Radio link budget (course-corrected Maxim AN5142 method)
A2: Blue = input, black = formula, yellow = key assumption to confirm by measurement. Losses are entered as NEGATIVE dB (AN5142 convention). Flat-earth uses the course correction (no 1/2 factor) and the course sheet's |cos| worst-case envelope.
A3: Block | B3: Variable | C3: Units | D3: Equation / source | E3: S1 | F3: S2 | G3: S3 | H3: S4 | I3: S5 | J3: S6 | K3: S7 | L3: S8 | M3: S9 | N3: S10 | O3: S11 | P3: S12 | Q3: S13 | R3: S14 | S3: S15
A4: Scenario
A5: Round | D5: Rules PDF: SRI 70 m, MRM ~260 m, NM hop (distance unknown) | E5: SRI 70 m | F5: SRI 70 m | G5: SRI 70 m | H5: SRI 70 m | I5: SRI 70 m | J5: SRI 70 m | K5: MRM 260 m | L5: MRM 260 m | M5: MRM 260 m | N5: MRM 260 m | O5: NM hop 100 m | P5: NM hop 100 m | Q5: MRM 260 m | R5: NM hop 100 m | S5: Bench 70 m
A6: Radio / configuration | E6: RFM69HCW 868 | 38.4 kbps | F6: RFM69HCW 868 | 100 kbps | G6: Si4463 868 | 100 kbps | H6: CC1101 868 | 38.4 kbps | I6: nRF24 2.4G | 1 Mbps | J6: nRF24 2.4G | 2 Mbps | K6: RFM69HCW 868 | 38.4 kbps | L6: Si4463 868 | 100 kbps | M6: nRF24 2.4G | 250 kbps | N6: nRF24 2.4G | 250 kbps, 8 dBi patches | O6: RFM69HCW 868 | 38.4 kbps, -10 dB obstr. | P6: nRF24 2.4G | 250 kbps, -10 dB obstr. | Q6: RFM69HCW 868 | 100 kbps (baseline) | R6: RFM69HCW 868 | 100 kbps, -10 dB obstr. (baseline) | S6: RFM69HCW 869.85 | 100 kbps, +9 dBm (BENCH_5MW)
A7: Air data rate | B7: R | C7: kbps | D7: Rate the sensitivity refers to | E7: 38.4 | F7: 100 | G7: 100 | H7: 38.4 | I7: 1000 | J7: 2000 | K7: 38.4 | L7: 100 | M7: 250 | N7: 250 | O7: 38.4 | P7: 250 | Q7: 100 | R7: 100 | S7: 100
A8: Regulatory limit type | D8: 868: e.r.p. (UN-39); 2.4 GHz: e.i.r.p. (UN-85 b) | E8: ERP | F8: ERP | G8: ERP | H8: ERP | I8: EIRP | J8: EIRP | K8: ERP | L8: ERP | M8: EIRP | N8: EIRP | O8: ERP | P8: EIRP | Q8: ERP | R8: ERP | S8: ERP
A9: Regulatory power limit | B9: Plim | C9: dBm | D9: 500 mW e.r.p. = 27 dBm; 10 mW e.i.r.p. = 10 dBm | E9: 27 | F9: 27 | G9: 27 | H9: 27 | I9: 10 | J9: 10 | K9: 27 | L9: 27 | M9: 10 | N9: 10 | O9: 27 | P9: 10 | Q9: 27 | R9: 27 | S9: 7
A10: System variables
A11: Frequency | B11: f0 | C11: MHz | D11: 869.525 = centre of 869.40-869.65 MHz | E11: 869.525 | F11: 869.525 | G11: 869.525 | H11: 869.525 | I11: 2440 | J11: 2440 | K11: 869.525 | L11: 869.525 | M11: 2440 | N11: 2440 | O11: 869.525 | P11: 2440 | Q11: 869.525 | R11: 869.525 | S11: 869.85
A12: Speed of light | B12: c | C12: m/s | D12: constant | E12: 299792458 | F12: 299792458 | G12: 299792458 | H12: 299792458 | I12: 299792458 | J12: 299792458 | K12: 299792458 | L12: 299792458 | M12: 299792458 | N12: 299792458 | O12: 299792458 | P12: 299792458 | Q12: 299792458 | R12: 299792458 | S12: 299792458
A13: Wavelength | B13: λ | C13: m | D13: λ = c / f0 | E13: =E12/(E11*1000000) | F13: =F12/(F11*1000000) | G13: =G12/(G11*1000000) | H13: =H12/(H11*1000000) | I13: =I12/(I11*1000000) | J13: =J12/(J11*1000000) | K13: =K12/(K11*1000000) | L13: =L12/(L11*1000000) | ... S13: =S12/(S11*1000000)
A14: Transmitter
A15: PA power | B15: PPA | C15: dBm | D15: Module setting (see Candidates sheet for limits) | E15: 17 | F15: 17 | G15: 20 | H15: 12 | I15: 0 | J15: 0 | K15: 17 | L15: 20 | M15: 0 | N15: 0 | O15: 17 | P15: 0 | Q15: 17 | R15: 17 | S15: 9
A16: TX match loss | B16: LMatchT | C16: dB | D16: ASSUMPTION | E16: -0.5 | F16: -0.5 | G16: -0.5 | H16: -0.5 | I16: 0 | J16: 0 | K16: -0.5 | L16: -0.5 | M16: 0 | N16: 0 | O16: -0.5 | P16: 0 | Q16: -0.5 | R16: -0.5 | S16: -0.5
A17: TX connector/cable loss | B17: LConT | C17: dB | D17: 0 if antenna soldered on PCB | E17: 0 | F17: 0 | G17: 0 | H17: 0 | I17: 0 | J17: 0 | K17: 0 | L17: 0 | M17: 0 | N17: 0 | O17: 0 | P17: 0 | Q17: 0 | R17: 0 | S17: 0
A18: TX power at antenna | B18: PT | C18: dBm | D18: PT = PPA + LMatchT + LConT | E18: =E15+E16+E17 | F18: =F15+F16+F17 | G18: =G15+G16+G17 | H18: =H15+H16+H17 | I18: =I15+I16+I17 | J18: =J15+J16+J17 | K18: =K15+K16+K17 | L18: =L15+L16+L17 | ... S18: =S15+S16+S17
A19: TX antenna gain (in box) | B19: GT | C19: dBi | D19: ASSUMPTION: incl. efficiency/detuning inside container | E19: 0 | F19: 0 | G19: 0 | H19: 0 | I19: 2 | J19: 2 | K19: 0 | L19: 0 | M19: 2 | N19: 8 | O19: 0 | P19: 2 | Q19: 0 | R19: 0 | S19: 0
A20: EIRP | B20: EIRP | C20: dBm | D20: EIRP = PT + GT | E20: =E18+E19 | F20: =F18+F19 | G20: =G18+G19 | H20: =H18+H19 | I20: =I18+I19 | J20: =J18+J19 | K20: =K18+K19 | L20: =L18+L19 | ... S20: =S18+S19
A21: ERP | B21: ERP | C21: dBm | D21: ERP = EIRP - 2.15 | E21: =E20-2.15 | F21: =F20-2.15 | G21: =G20-2.15 | H21: =H20-2.15 | I21: =I20-2.15 | J21: =J20-2.15 | K21: =K20-2.15 | L21: =L20-2.15 | ... S21: =S20-2.15
A22: Regulatory check | D22: Compare ERP or EIRP with limit | E22: =IF(IF(E8="ERP",E21,E20)<=E9,"OK","OVER LIMIT") | F22: =IF(IF(F8="ERP",F21,F20)<=F9,"OK","OVER LIMIT") | G22: =IF(IF(G8="ERP",G21,G20)<=G9,"OK","OVER LIMIT") | H22: =IF(IF(H8="ERP",H21,H20)<=H9,"OK","OVER LIMIT") | I22: =IF(IF(I8="ERP",I21,I20)<=I9,"OK","OVER LIMIT") | J22: =IF(IF(J8="ERP",J21,J20)<=J9,"OK","OVER LIMIT") | K22: =IF(IF(K8="ERP",K21,K20)<=K9,"OK","OVER LIMIT") | L22: =IF(IF(L8="ERP",L21,L20)<=L9,"OK","OVER LIMIT") | ... S22: =IF(IF(S8="ERP",S21,S20)<=S9,"OK","OVER LIMIT")
A23: Path
A24: Distance | B24: d | C24: m | E24: 70 | F24: 70 | G24: 70 | H24: 70 | I24: 70 | J24: 70 | K24: 260 | L24: 260 | M24: 260 | N24: 260 | O24: 100 | P24: 100 | Q24: 260 | R24: 100 | S24: 70
A25: TX antenna height | B25: hTX | C25: m | D25: 70 cm support [RULE 'about 70 cm'] + position in box | E25: 0.75 | F25: 0.75 | G25: 0.75 | H25: 0.75 | I25: 0.75 | J25: 0.75 | K25: 0.75 | L25: 0.75 | M25: 0.75 | N25: 0.75 | O25: 0.75 | P25: 0.75 | Q25: 0.75 | R25: 0.75 | S25: 0.75
A26: RX antenna height | B26: hRX | C26: m | E26: 0.75 | F26: 0.75 | G26: 0.75 | H26: 0.75 | I26: 0.75 | J26: 0.75 | K26: 0.75 | L26: 0.75 | M26: 0.75 | N26: 0.75 | O26: 0.75 | P26: 0.75 | Q26: 0.75 | R26: 0.75 | S26: 0.75
A27: Ground bounce amplitude | B27: a | C27: - | D27: 1 = worst case (course sheet default) | E27: 1 | F27: 1 | G27: 1 | H27: 1 | I27: 1 | J27: 1 | K27: 1 | L27: 1 | M27: 1 | N27: 1 | O27: 1 | P27: 1 | Q27: 1 | R27: 1 | S27: 1
A28: Reflection path Δ | B28: Δd | C28: m | D28: Δd = √(d²+(hTX+hRX)²) - √(d²+(hTX-hRX)²) | E28: =SQRT(E24^2+(E25+E26)^2)-SQRT(E24^2+(E25-E26)^2) | F28: =SQRT(F24^2+(F25+F26)^2)-SQRT(F24^2+(F25-F26)^2) | G28: =SQRT(G24^2+(G25+G26)^2)-SQRT(G24^2+(G25-G26)^2) | H28: =SQRT(H24^2+(H25+H26)^2)-SQRT(H24^2+(H25-H26)^2) | I28: =SQRT(I24^2+(I25+I26)^2)-SQRT(I24^2+(I25-I26)^2) | J28: =SQRT(J24^2+(J25+J26)^2)-SQRT(J24^2+(J25-J26)^2) | K28: =SQRT(K24^2+(K25+K26)^2)-SQRT(K24^2+(K25-K26)^2) | L28: =SQRT(L24^2+(L25+L26)^2)-SQRT(L24^2+(L25-L26)^2) | ... S28: =SQRT(S24^2+(S25+S26)^2)-SQRT(S24^2+(S25-S26)^2)
A29: Ground-bounce phase | B29: x | C29: rad | D29: x = 2π·Δd/λ | E29: =2*PI()*E28/E13 | F29: =2*PI()*F28/F13 | G29: =2*PI()*G28/G13 | H29: =2*PI()*H28/H13 | I29: =2*PI()*I28/I13 | J29: =2*PI()*J28/J13 | K29: =2*PI()*K28/K13 | L29: =2*PI()*L28/L13 | ... S29: =2*PI()*S28/S13
A30: Propagation regime | D30: x < π/2: smooth d^-4 region; else interference zone (|cos| creates artificial nulls) | E30: =IF(E29<PI()/2,"beyond breakpoint","interference zone") | F30: =IF(F29<PI()/2,"beyond breakpoint","interference zone") | G30: =IF(G29<PI()/2,"beyond breakpoint","interference zone") | H30: =IF(H29<PI()/2,"beyond breakpoint","interference zone") | I30: =IF(I29<PI()/2,"beyond breakpoint","interference zone") | J30: =IF(J29<PI()/2,"beyond breakpoint","interference zone") | K30: =IF(K29<PI()/2,"beyond breakpoint","interference zone") | L30: =IF(L29<PI()/2,"beyond breakpoint","interference zone") | ... S30: =IF(S29<PI()/2,"beyond breakpoint","interference zone")
A31: Free space loss | B31: LFS | C31: dB | D31: LFS = 20·log10(λ / 4πd) | E31: =20*LOG10(E13/(4*PI()*E24)) | F31: =20*LOG10(F13/(4*PI()*F24)) | G31: =20*LOG10(G13/(4*PI()*G24)) | H31: =20*LOG10(H13/(4*PI()*H24)) | I31: =20*LOG10(I13/(4*PI()*I24)) | J31: =20*LOG10(J13/(4*PI()*J24)) | K31: =20*LOG10(K13/(4*PI()*K24)) | L31: =20*LOG10(L13/(4*PI()*L24)) | ... S31: =20*LOG10(S13/(4*PI()*S24))
A32: Ground bounce loss | B32: LGB | C32: dB | D32: LGB = 10·log10(1 + a² - 2a·|cos x|) [course-corrected, no 1/2] | E32: =10*LOG10(1+E27^2-2*E27*ABS(COS(E29))) | F32: =10*LOG10(1+F27^2-2*F27*ABS(COS(F29))) | G32: =10*LOG10(1+G27^2-2*G27*ABS(COS(G29))) | H32: =10*LOG10(1+H27^2-2*H27*ABS(COS(H29))) | I32: =10*LOG10(1+I27^2-2*I27*ABS(COS(I29))) | J32: =10*LOG10(1+J27^2-2*J27*ABS(COS(J29))) | K32: =10*LOG10(1+K27^2-2*K27*ABS(COS(K29))) | L32: =10*LOG10(1+L27^2-2*L27*ABS(COS(L29))) | ... S32: =10*LOG10(1+S27^2-2*S27*ABS(COS(S29)))
A33: Flat earth loss | B33: LFE | C33: dB | D33: LFE = LFS + LGB | E33: =E31+E32 | F33: =F31+F32 | G33: =G31+G32 | H33: =H31+H32 | I33: =I31+I32 | J33: =J31+J32 | K33: =K31+K32 | L33: =L31+L32 | ... S33: =S31+S32
A34: Medium / container loss | B34: L0 | C34: dB | D34: ASSUMPTION: IKEA 365+ PP lid/walls; measure open vs closed (T5) | E34: -1 | F34: -1 | G34: -1 | H34: -1 | I34: -1 | J34: -1 | K34: -1 | L34: -1 | M34: -1 | N34: -1 | O34: -1 | P34: -1 | Q34: -1 | R34: -1 | S34: -1
A35: Multipath loss | B35: LMP | C35: dB | D35: ASSUMPTION: 0 on open campus paths; AN5142 suggests ≥20 dB in cluttered areas | E35: 0 | F35: 0 | G35: 0 | H35: 0 | I35: 0 | J35: 0 | K35: 0 | L35: 0 | M35: 0 | N35: 0 | O35: 0 | P35: 0 | Q35: 0 | R35: 0 | S35: 0
A36: Obstruction loss | B36: LObs | C36: dB | D36: NM: building corner ASSUMED -10 dB | E36: 0 | F36: 0 | G36: 0 | H36: 0 | I36: 0 | J36: 0 | K36: 0 | L36: 0 | M36: 0 | N36: 0 | O36: -10 | P36: -10 | Q36: 0 | R36: -10 | S36: 0
A37: Power at RX antenna, free space | B37: PChanFS | C37: dBm | D37: PChanFS = EIRP + LFS + L0 | E37: =E20+E31+E34 | F37: =F20+F31+F34 | G37: =G20+G31+G34 | H37: =H20+H31+H34 | I37: =I20+I31+I34 | J37: =J20+J31+J34 | K37: =K20+K31+K34 | L37: =L20+L31+L34 | ... S37: =S20+S31+S34
A38: Power at RX antenna, flat earth | B38: PChanFE | C38: dBm | D38: PChanFE = EIRP + LFE + L0 + LMP + LObs | E38: =E20+E33+E34+E35+E36 | F38: =F20+F33+F34+F35+F36 | G38: =G20+G33+G34+G35+G36 | H38: =H20+H33+H34+H35+H36 | I38: =I20+I33+I34+I35+I36 | J38: =J20+J33+J34+J35+J36 | K38: =K20+K33+K34+K35+K36 | L38: =L20+L33+L34+L35+L36 | ... S38: =S20+S33+S34+S35+S36
A39: Receiver
A40: RX antenna gain (in box) | B40: GR | C40: dBi | D40: ASSUMPTION | E40: 0 | F40: 0 | G40: 0 | H40: 0 | I40: 2 | J40: 2 | K40: 0 | L40: 0 | M40: 2 | N40: 8 | O40: 0 | P40: 2 | Q40: 0 | R40: 0 | S40: 0
...

Sheet Height Sweep
A1: Flat-earth margin (dB) vs common antenna height (both ends) - beyond the breakpoint, margin grows 20·log10(h1·h2)
A2: Each cell recomputes the Link Budget column with hTX = hRX = height in row 4. Values in the 'interference zone' (see Link Budget regime row) can show artificial |cos| nulls.
A4: Scenario \ height (m) | B4: 0.5 | C4: 0.75 | D4: 1 | E4: 1.25 | F4: 1.5
A5: ="S1 "&'Link Budget'!E5&" | "&'Link Budget'!E6 | B5: ='Link Budget'!E20+20*LOG10('Link Budget'!E13/(4*PI()*'Link Budget'!E24))+10*LOG10(1+'Link Budget'!E27^2-2*'Link Budget'!E27*ABS(COS(2*PI()*(SQRT('Link Budget'!E24^2+(2*B$4)^2)-'Link Budget'!E24)/'Link Budget'!E13)))+'Link Budget'!E34+'Link Budget'!E35+'Link Budget'!E36+'Link Budget'!E40+'Link Budget'!E41-'Link Budget'!E44 | C5: ='Link Budget'!E20+20*LOG10('Link Budget'!E13/(4*PI()*'Link Budget'!E24))+10*LOG10(1+'Link Budget'!E27^2-2*'Link Budget'!E27*ABS(COS(2*PI()*(SQRT('Link Budget'!E24^2+(2*C$4)^2)-'Link Budget'!E24)/'Link Budget'!E13)))+'Link Budget'!E34+'Link Budget'!E35+'Link Budget'!E36+'Link Budget'!E40+'Link Budget'!E41-'Link Budget'!E44 | D5: ='Link Budget'!E20+20*LOG10('Link Budget'!E13/(4*PI()*'Link Budget'!E24))+10*LOG10(1+'Link Budget'!E27^2-2*'Link Budget'!E27*ABS(COS(2*PI()*(SQRT('Link Budget'!E24^2+(2*D$4)^2)-'Link Budget'!E24)/'Link Budget'!E13)))+'Link Budget'!E34+'Link Budget'!E35+'Link Budget'!E36+'Link Budget'!E40+'Link Budget'!E41-'Link Budget'!E44 | E5: ='Link Budget'!E20+20*LOG10('Link Budget'!E13/(4*PI()*'Link Budget'!E24))+10*LOG10(1+'Link Budget'!E27^2-2*'Link Budget'!E27*ABS(COS(2*PI()*(SQRT('Link Budget'!E24^2+(2*E$4)^2)-'Link Budget'!E24)/'Link Budget'!E13)))+'Link Budget'!E34+'Link Budget'!E35+'Link Budget'!E36+'Link Budget'!E40+'Link Budget'!E41-'Link Budget'!E44 | F5: ='Link Budget'!E20+20*LOG10('Link Budget'!E13/(4*PI()*'Link Budget'!E24))+10*LOG10(1+'Link Budget'!E27^2-2*'Link Budget'!E27*ABS(COS(2*PI()*(SQRT('Link Budget'!E24^2+(2*F$4)^2)-'Link Budget'!E24)/'Link Budget'!E13)))+'Link Budget'!E34+'Link Budget'!E35+'Link Budget'!E36+'Link Budget'!E40+'Link Budget'!E41-'Link Budget'!E44
A6: ="S2 "&'Link Budget'!F5&" | "&'Link Budget'!F6 | B6: ='Link Budget'!F20+20*LOG10('Link Budget'!F13/(4*PI()*'Link Budget'!F24))+10*LOG10(1+'Link Budget'!F27^2-2*'Link Budget'!F27*ABS(COS(2*PI()*(SQRT('Link Budget'!F24^2+(2*B$4)^2)-'Link Budget'!F24)/'Link Budget'!F13)))+'Link Budget'!F34+'Link Budget'!F35+'Link Budget'!F36+'Link Budget'!F40+'Link Budget'!F41-'Link Budget'!F44 | C6: ='Link Budget'!F20+20*LOG10('Link Budget'!F13/(4*PI()*'Link Budget'!F24))+10*LOG10(1+'Link Budget'!F27^2-2*'Link Budget'!F27*ABS(COS(2*PI()*(SQRT('Link Budget'!F24^2+(2*C$4)^2)-'Link Budget'!F24)/'Link Budget'!F13)))+'Link Budget'!F34+'Link Budget'!F35+'Link Budget'!F36+'Link Budget'!F40+'Link Budget'!F41-'Link Budget'!F44 | D6: ='Link Budget'!F20+20*LOG10('Link Budget'!F13/(4*PI()*'Link Budget'!F24))+10*LOG10(1+'Link Budget'!F27^2-2*'Link Budget'!F27*ABS(COS(2*PI()*(SQRT('Link Budget'!F24^2+(2*D$4)^2)-'Link Budget'!F24)/'Link Budget'!F13)))+'Link Budget'!F34+'Link Budget'!F35+'Link Budget'!F36+'Link Budget'!F40+'Link Budget'!F41-'Link Budget'!F44 | E6: ='Link Budget'!F20+20*LOG10('Link Budget'!F13/(4*PI()*'Link Budget'!F24))+10*LOG10(1+'Link Budget'!F27^2-2*'Link Budget'!F27*ABS(COS(2*PI()*(SQRT('Link Budget'!F24^2+(2*E$4)^2)-'Link Budget'!F24)/'Link Budget'!F13)))+'Link Budget'!F34+'Link Budget'!F35+'Link Budget'!F36+'Link Budget'!F40+'Link Budget'!F41-'Link Budget'!F44 | F6: ='Link Budget'!F20+20*LOG10('Link Budget'!F13/(4*PI()*'Link Budget'!F24))+10*LOG10(1+'Link Budget'!F27^2-2*'Link Budget'!F27*ABS(COS(2*PI()*(SQRT('Link Budget'!F24^2+(2*F$4)^2)-'Link Budget'!F24)/'Link Budget'!F13)))+'Link Budget'!F34+'Link Budget'!F35+'Link Budget'!F36+'Link Budget'!F40+'Link Budget'!F41-'Link Budget'!F44
A7: ="S3 "&'Link Budget'!G5&" | "&'Link Budget'!G6 | B7: ='Link Budget'!G20+20*LOG10('Link Budget'!G13/(4*PI()*'Link Budget'!G24))+10*LOG10(1+'Link Budget'!G27^2-2*'Link Budget'!G27*ABS(COS(2*PI()*(SQRT('Link Budget'!G24^2+(2*B$4)^2)-'Link Budget'!G24)/'Link Budget'!G13)))+'Link Budget'!G34+'Link Budget'!G35+'Link Budget'!G36+'Link Budget'!G40+'Link Budget'!G41-'Link Budget'!G44 | C7: ='Link Budget'!G20+20*LOG10('Link Budget'!G13/(4*PI()*'Link Budget'!G24))+10*LOG10(1+'Link Budget'!G27^2-2*'Link Budget'!G27*ABS(COS(2*PI()*(SQRT('Link Budget'!G24^2+(2*C$4)^2)-'Link Budget'!G24)/'Link Budget'!G13)))+'Link Budget'!G34+'Link Budget'!G35+'Link Budget'!G36+'Link Budget'!G40+'Link Budget'!G41-'Link Budget'!G44 | D7: ='Link Budget'!G20+20*LOG10('Link Budget'!G13/(4*PI()*'Link Budget'!G24))+10*LOG10(1+'Link Budget'!G27^2-2*'Link Budget'!G27*ABS(COS(2*PI()*(SQRT('Link Budget'!G24^2+(2*D$4)^2)-'Link Budget'!G24)/'Link Budget'!G13)))+'Link Budget'!G34+'Link Budget'!G35+'Link Budget'!G36+'Link Budget'!G40+'Link Budget'!G41-'Link Budget'!G44 | E7: ='Link Budget'!G20+20*LOG10('Link Budget'!G13/(4*PI()*'Link Budget'!G24))+10*LOG10(1+'Link Budget'!G27^2-2*'Link Budget'!G27*ABS(COS(2*PI()*(SQRT('Link Budget'!G24^2+(2*E$4)^2)-'Link Budget'!G24)/'Link Budget'!G13)))+'Link Budget'!G34+'Link Budget'!G35+'Link Budget'!G36+'Link Budget'!G40+'Link Budget'!G41-'Link Budget'!G44 | F7: ='Link Budget'!G20+20*LOG10('Link Budget'!G13/(4*PI()*'Link Budget'!G24))+10*LOG10(1+'Link Budget'!G27^2-2*'Link Budget'!G27*ABS(COS(2*PI()*(SQRT('Link Budget'!G24^2+(2*F$4)^2)-'Link Budget'!G24)/'Link Budget'!G13)))+'Link Budget'!G34+'Link Budget'!G35+'Link Budget'!G36+'Link Budget'!G40+'Link Budget'!G41-'Link Budget'!G44
A8: ="S4 "&'Link Budget'!H5&" | "&'Link Budget'!H6 | B8: ='Link Budget'!H20+20*LOG10('Link Budget'!H13/(4*PI()*'Link Budget'!H24))+10*LOG10(1+'Link Budget'!H27^2-2*'Link Budget'!H27*ABS(COS(2*PI()*(SQRT('Link Budget'!H24^2+(2*B$4)^2)-'Link Budget'!H24)/'Link Budget'!H13)))+'Link Budget'!H34+'Link Budget'!H35+'Link Budget'!H36+'Link Budget'!H40+'Link Budget'!H41-'Link Budget'!H44 | C8: ='Link Budget'!H20+20*LOG10('Link Budget'!H13/(4*PI()*'Link Budget'!H24))+10*LOG10(1+'Link Budget'!H27^2-2*'Link Budget'!H27*ABS(COS(2*PI()*(SQRT('Link Budget'!H24^2+(2*C$4)^2)-'Link Budget'!H24)/'Link Budget'!H13)))+'Link Budget'!H34+'Link Budget'!H35+'Link Budget'!H36+'Link Budget'!H40+'Link Budget'!H41-'Link Budget'!H44 | D8: ='Link Budget'!H20+20*LOG10('Link Budget'!H13/(4*PI()*'Link Budget'!H24))+10*LOG10(1+'Link Budget'!H27^2-2*'Link Budget'!H27*ABS(COS(2*PI()*(SQRT('Link Budget'!H24^2+(2*D$4)^2)-'Link Budget'!H24)/'Link Budget'!H13)))+'Link Budget'!H34+'Link Budget'!H35+'Link Budget'!H36+'Link Budget'!H40+'Link Budget'!H41-'Link Budget'!H44 | E8: ='Link Budget'!H20+20*LOG10('Link Budget'!H13/(4*PI()*'Link Budget'!H24))+10*LOG10(1+'Link Budget'!H27^2-2*'Link Budget'!H27*ABS(COS(2*PI()*(SQRT('Link Budget'!H24^2+(2*E$4)^2)-'Link Budget'!H24)/'Link Budget'!H13)))+'Link Budget'!H34+'Link Budget'!H35+'Link Budget'!H36+'Link Budget'!H40+'Link Budget'!H41-'Link Budget'!H44 | F8: ='Link Budget'!H20+20*LOG10('Link Budget'!H13/(4*PI()*'Link Budget'!H24))+10*LOG10(1+'Link Budget'!H27^2-2*'Link Budget'!H27*ABS(COS(2*PI()*(SQRT('Link Budget'!H24^2+(2*F$4)^2)-'Link Budget'!H24)/'Link Budget'!H13)))+'Link Budget'!H34+'Link Budget'!H35+'Link Budget'!H36+'Link Budget'!H40+'Link Budget'!H41-'Link Budget'!H44
A9: ="S5 "&'Link Budget'!I5&" | "&'Link Budget'!I6 | B9: ='Link Budget'!I20+20*LOG10('Link Budget'!I13/(4*PI()*'Link Budget'!I24))+10*LOG10(1+'Link Budget'!I27^2-2*'Link Budget'!I27*ABS(COS(2*PI()*(SQRT('Link Budget'!I24^2+(2*B$4)^2)-'Link Budget'!I24)/'Link Budget'!I13)))+'Link Budget'!I34+'Link Budget'!I35+'Link Budget'!I36+'Link Budget'!I40+'Link Budget'!I41-'Link Budget'!I44 | C9: ='Link Budget'!I20+20*LOG10('Link Budget'!I13/(4*PI()*'Link Budget'!I24))+10*LOG10(1+'Link Budget'!I27^2-2*'Link Budget'!I27*ABS(COS(2*PI()*(SQRT('Link Budget'!I24^2+(2*C$4)^2)-'Link Budget'!I24)/'Link Budget'!I13)))+'Link Budget'!I34+'Link Budget'!I35+'Link Budget'!I36+'Link Budget'!I40+'Link Budget'!I41-'Link Budget'!I44 | D9: ='Link Budget'!I20+20*LOG10('Link Budget'!I13/(4*PI()*'Link Budget'!I24))+10*LOG10(1+'Link Budget'!I27^2-2*'Link Budget'!I27*ABS(COS(2*PI()*(SQRT('Link Budget'!I24^2+(2*D$4)^2)-'Link Budget'!I24)/'Link Budget'!I13)))+'Link Budget'!I34+'Link Budget'!I35+'Link Budget'!I36+'Link Budget'!I40+'Link Budget'!I41-'Link Budget'!I44 | E9: ='Link Budget'!I20+20*LOG10('Link Budget'!I13/(4*PI()*'Link Budget'!I24))+10*LOG10(1+'Link Budget'!I27^2-2*'Link Budget'!I27*ABS(COS(2*PI()*(SQRT('Link Budget'!I24^2+(2*E$4)^2)-'Link Budget'!I24)/'Link Budget'!I13)))+'Link Budget'!I34+'Link Budget'!I35+'Link Budget'!I36+'Link Budget'!I40+'Link Budget'!I41-'Link Budget'!I44 | F9: ='Link Budget'!I20+20*LOG10('Link Budget'!I13/(4*PI()*'Link Budget'!I24))+10*LOG10(1+'Link Budget'!I27^2-2*'Link Budget'!I27*ABS(COS(2*PI()*(SQRT('Link Budget'!I24^2+(2*F$4)^2)-'Link Budget'!I24)/'Link Budget'!I13)))+'Link Budget'!I34+'Link Budget'!I35+'Link Budget'!I36+'Link Budget'!I40+'Link Budget'!I41-'Link Budget'!I44
A10: ="S6 "&'Link Budget'!J5&" | "&'Link Budget'!J6 | B10: ='Link Budget'!J20+20*LOG10('Link Budget'!J13/(4*PI()*'Link Budget'!J24))+10*LOG10(1+'Link Budget'!J27^2-2*'Link Budget'!J27*ABS(COS(2*PI()*(SQRT('Link Budget'!J24^2+(2*B$4)^2)-'Link Budget'!J24)/'Link Budget'!J13)))+'Link Budget'!J34+'Link Budget'!J35+'Link Budget'!J36+'Link Budget'!J40+'Link Budget'!J41-'Link Budget'!J44 | C10: ='Link Budget'!J20+20*LOG10('Link Budget'!J13/(4*PI()*'Link Budget'!J24))+10*LOG10(1+'Link Budget'!J27^2-2*'Link Budget'!J27*ABS(COS(2*PI()*(SQRT('Link Budget'!J24^2+(2*C$4)^2)-'Link Budget'!J24)/'Link Budget'!J13)))+'Link Budget'!J34+'Link Budget'!J35+'Link Budget'!J36+'Link Budget'!J40+'Link Budget'!J41-'Link Budget'!J44 | D10: ='Link Budget'!J20+20*LOG10('Link Budget'!J13/(4*PI()*'Link Budget'!J24))+10*LOG10(1+'Link Budget'!J27^2-2*'Link Budget'!J27*ABS(COS(2*PI()*(SQRT('Link Budget'!J24^2+(2*D$4)^2)-'Link Budget'!J24)/'Link Budget'!J13)))+'Link Budget'!J34+'Link Budget'!J35+'Link Budget'!J36+'Link Budget'!J40+'Link Budget'!J41-'Link Budget'!J44 | E10: ='Link Budget'!J20+20*LOG10('Link Budget'!J13/(4*PI()*'Link Budget'!J24))+10*LOG10(1+'Link Budget'!J27^2-2*'Link Budget'!J27*ABS(COS(2*PI()*(SQRT('Link Budget'!J24^2+(2*E$4)^2)-'Link Budget'!J24)/'Link Budget'!J13)))+'Link Budget'!J34+'Link Budget'!J35+'Link Budget'!J36+'Link Budget'!J40+'Link Budget'!J41-'Link Budget'!J44 | F10: ='Link Budget'!J20+20*LOG10('Link Budget'!J13/(4*PI()*'Link Budget'!J24))+10*LOG10(1+'Link Budget'!J27^2-2*'Link Budget'!J27*ABS(COS(2*PI()*(SQRT('Link Budget'!J24^2+(2*F$4)^2)-'Link Budget'!J24)/'Link Budget'!J13)))+'Link Budget'!J34+'Link Budget'!J35+'Link Budget'!J36+'Link Budget'!J40+'Link Budget'!J41-'Link Budget'!J44
A11: ="S7 "&'Link Budget'!K5&" | "&'Link Budget'!K6 | B11: ='Link Budget'!K20+20*LOG10('Link Budget'!K13/(4*PI()*'Link Budget'!K24))+10*LOG10(1+'Link Budget'!K27^2-2*'Link Budget'!K27*ABS(COS(2*PI()*(SQRT('Link Budget'!K24^2+(2*B$4)^2)-'Link Budget'!K24)/'Link Budget'!K13)))+'Link Budget'!K34+'Link Budget'!K35+'Link Budget'!K36+'Link Budget'!K40+'Link Budget'!K41-'Link Budget'!K44 | C11: ='Link Budget'!K20+20*LOG10('Link Budget'!K13/(4*PI()*'Link Budget'!K24))+10*LOG10(1+'Link Budget'!K27^2-2*'Link Budget'!K27*ABS(COS(2*PI()*(SQRT('Link Budget'!K24^2+(2*C$4)^2)-'Link Budget'!K24)/'Link Budget'!K13)))+'Link Budget'!K34+'Link Budget'!K35+'Link Budget'!K36+'Link Budget'!K40+'Link Budget'!K41-'Link Budget'!K44 | D11: ='Link Budget'!K20+20*LOG10('Link Budget'!K13/(4*PI()*'Link Budget'!K24))+10*LOG10(1+'Link Budget'!K27^2-2*'Link Budget'!K27*ABS(COS(2*PI()*(SQRT('Link Budget'!K24^2+(2*D$4)^2)-'Link Budget'!K24)/'Link Budget'!K13)))+'Link Budget'!K34+'Link Budget'!K35+'Link Budget'!K36+'Link Budget'!K40+'Link Budget'!K41-'Link Budget'!K44 | E11: ='Link Budget'!K20+20*LOG10('Link Budget'!K13/(4*PI()*'Link Budget'!K24))+10*LOG10(1+'Link Budget'!K27^2-2*'Link Budget'!K27*ABS(COS(2*PI()*(SQRT('Link Budget'!K24^2+(2*E$4)^2)-'Link Budget'!K24)/'Link Budget'!K13)))+'Link Budget'!K34+'Link Budget'!K35+'Link Budget'!K36+'Link Budget'!K40+'Link Budget'!K41-'Link Budget'!K44 | F11: ='Link Budget'!K20+20*LOG10('Link Budget'!K13/(4*PI()*'Link Budget'!K24))+10*LOG10(1+'Link Budget'!K27^2-2*'Link Budget'!K27*ABS(COS(2*PI()*(SQRT('Link Budget'!K24^2+(2*F$4)^2)-'Link Budget'!K24)/'Link Budget'!K13)))+'Link Budget'!K34+'Link Budget'!K35+'Link Budget'!K36+'Link Budget'!K40+'Link Budget'!K41-'Link Budget'!K44
A12: ="S8 "&'Link Budget'!L5&" | "&'Link Budget'!L6 | B12: ='Link Budget'!L20+20*LOG10('Link Budget'!L13/(4*PI()*'Link Budget'!L24))+10*LOG10(1+'Link Budget'!L27^2-2*'Link Budget'!L27*ABS(COS(2*PI()*(SQRT('Link Budget'!L24^2+(2*B$4)^2)-'Link Budget'!L24)/'Link Budget'!L13)))+'Link Budget'!L34+'Link Budget'!L35+'Link Budget'!L36+'Link Budget'!L40+'Link Budget'!L41-'Link Budget'!L44 | C12: ='Link Budget'!L20+20*LOG10('Link Budget'!L13/(4*PI()*'Link Budget'!L24))+10*LOG10(1+'Link Budget'!L27^2-2*'Link Budget'!L27*ABS(COS(2*PI()*(SQRT('Link Budget'!L24^2+(2*C$4)^2)-'Link Budget'!L24)/'Link Budget'!L13)))+'Link Budget'!L34+'Link Budget'!L35+'Link Budget'!L36+'Link Budget'!L40+'Link Budget'!L41-'Link Budget'!L44 | D12: ='Link Budget'!L20+20*LOG10('Link Budget'!L13/(4*PI()*'Link Budget'!L24))+10*LOG10(1+'Link Budget'!L27^2-2*'Link Budget'!L27*ABS(COS(2*PI()*(SQRT('Link Budget'!L24^2+(2*D$4)^2)-'Link Budget'!L24)/'Link Budget'!L13)))+'Link Budget'!L34+'Link Budget'!L35+'Link Budget'!L36+'Link Budget'!L40+'Link Budget'!L41-'Link Budget'!L44 | E12: ='Link Budget'!L20+20*LOG10('Link Budget'!L13/(4*PI()*'Link Budget'!L24))+10*LOG10(1+'Link Budget'!L27^2-2*'Link Budget'!L27*ABS(COS(2*PI()*(SQRT('Link Budget'!L24^2+(2*E$4)^2)-'Link Budget'!L24)/'Link Budget'!L13)))+'Link Budget'!L34+'Link Budget'!L35+'Link Budget'!L36+'Link Budget'!L40+'Link Budget'!L41-'Link Budget'!L44 | F12: ='Link Budget'!L20+20*LOG10('Link Budget'!L13/(4*PI()*'Link Budget'!L24))+10*LOG10(1+'Link Budget'!L27^2-2*'Link Budget'!L27*ABS(COS(2*PI()*(SQRT('Link Budget'!L24^2+(2*F$4)^2)-'Link Budget'!L24)/'Link Budget'!L13)))+'Link Budget'!L34+'Link Budget'!L35+'Link Budget'!L36+'Link Budget'!L40+'Link Budget'!L41-'Link Budget'!L44
A13: ="S9 "&'Link Budget'!M5&" | "&'Link Budget'!M6 | B13: ='Link Budget'!M20+20*LOG10('Link Budget'!M13/(4*PI()*'Link Budget'!M24))+10*LOG10(1+'Link Budget'!M27^2-2*'Link Budget'!M27*ABS(COS(2*PI()*(SQRT('Link Budget'!M24^2+(2*B$4)^2)-'Link Budget'!M24)/'Link Budget'!M13)))+'Link Budget'!M34+'Link Budget'!M35+'Link Budget'!M36+'Link Budget'!M40+'Link Budget'!M41-'Link Budget'!M44 | C13: ='Link Budget'!M20+20*LOG10('Link Budget'!M13/(4*PI()*'Link Budget'!M24))+10*LOG10(1+'Link Budget'!M27^2-2*'Link Budget'!M27*ABS(COS(2*PI()*(SQRT('Link Budget'!M24^2+(2*C$4)^2)-'Link Budget'!M24)/'Link Budget'!M13)))+'Link Budget'!M34+'Link Budget'!M35+'Link Budget'!M36+'Link Budget'!M40+'Link Budget'!M41-'Link Budget'!M44 | D13: ='Link Budget'!M20+20*LOG10('Link Budget'!M13/(4*PI()*'Link Budget'!M24))+10*LOG10(1+'Link Budget'!M27^2-2*'Link Budget'!M27*ABS(COS(2*PI()*(SQRT('Link Budget'!M24^2+(2*D$4)^2)-'Link Budget'!M24)/'Link Budget'!M13)))+'Link Budget'!M34+'Link Budget'!M35+'Link Budget'!M36+'Link Budget'!M40+'Link Budget'!M41-'Link Budget'!M44 | E13: ='Link Budget'!M20+20*LOG10('Link Budget'!M13/(4*PI()*'Link Budget'!M24))+10*LOG10(1+'Link Budget'!M27^2-2*'Link Budget'!M27*ABS(COS(2*PI()*(SQRT('Link Budget'!M24^2+(2*E$4)^2)-'Link Budget'!M24)/'Link Budget'!M13)))+'Link Budget'!M34+'Link Budget'!M35+'Link Budget'!M36+'Link Budget'!M40+'Link Budget'!M41-'Link Budget'!M44 | F13: ='Link Budget'!M20+20*LOG10('Link Budget'!M13/(4*PI()*'Link Budget'!M24))+10*LOG10(1+'Link Budget'!M27^2-2*'Link Budget'!M27*ABS(COS(2*PI()*(SQRT('Link Budget'!M24^2+(2*F$4)^2)-'Link Budget'!M24)/'Link Budget'!M13)))+'Link Budget'!M34+'Link Budget'!M35+'Link Budget'!M36+'Link Budget'!M40+'Link Budget'!M41-'Link Budget'!M44
A14: ="S10 "&'Link Budget'!N5&" | "&'Link Budget'!N6 | B14: ='Link Budget'!N20+20*LOG10('Link Budget'!N13/(4*PI()*'Link Budget'!N24))+10*LOG10(1+'Link Budget'!N27^2-2*'Link Budget'!N27*ABS(COS(2*PI()*(SQRT('Link Budget'!N24^2+(2*B$4)^2)-'Link Budget'!N24)/'Link Budget'!N13)))+'Link Budget'!N34+'Link Budget'!N35+'Link Budget'!N36+'Link Budget'!N40+'Link Budget'!N41-'Link Budget'!N44 | C14: ='Link Budget'!N20+20*LOG10('Link Budget'!N13/(4*PI()*'Link Budget'!N24))+10*LOG10(1+'Link Budget'!N27^2-2*'Link Budget'!N27*ABS(COS(2*PI()*(SQRT('Link Budget'!N24^2+(2*C$4)^2)-'Link Budget'!N24)/'Link Budget'!N13)))+'Link Budget'!N34+'Link Budget'!N35+'Link Budget'!N36+'Link Budget'!N40+'Link Budget'!N41-'Link Budget'!N44 | D14: ='Link Budget'!N20+20*LOG10('Link Budget'!N13/(4*PI()*'Link Budget'!N24))+10*LOG10(1+'Link Budget'!N27^2-2*'Link Budget'!N27*ABS(COS(2*PI()*(SQRT('Link Budget'!N24^2+(2*D$4)^2)-'Link Budget'!N24)/'Link Budget'!N13)))+'Link Budget'!N34+'Link Budget'!N35+'Link Budget'!N36+'Link Budget'!N40+'Link Budget'!N41-'Link Budget'!N44 | E14: ='Link Budget'!N20+20*LOG10('Link Budget'!N13/(4*PI()*'Link Budget'!N24))+10*LOG10(1+'Link Budget'!N27^2-2*'Link Budget'!N27*ABS(COS(2*PI()*(SQRT('Link Budget'!N24^2+(2*E$4)^2)-'Link Budget'!N24)/'Link Budget'!N13)))+'Link Budget'!N34+'Link Budget'!N35+'Link Budget'!N36+'Link Budget'!N40+'Link Budget'!N41-'Link Budget'!N44 | F14: ='Link Budget'!N20+20*LOG10('Link Budget'!N13/(4*PI()*'Link Budget'!N24))+10*LOG10(1+'Link Budget'!N27^2-2*'Link Budget'!N27*ABS(COS(2*PI()*(SQRT('Link Budget'!N24^2+(2*F$4)^2)-'Link Budget'!N24)/'Link Budget'!N13)))+'Link Budget'!N34+'Link Budget'!N35+'Link Budget'!N36+'Link Budget'!N40+'Link Budget'!N41-'Link Budget'!N44
A15: ="S11 "&'Link Budget'!O5&" | "&'Link Budget'!O6 | B15: ='Link Budget'!O20+20*LOG10('Link Budget'!O13/(4*PI()*'Link Budget'!O24))+10*LOG10(1+'Link Budget'!O27^2-2*'Link Budget'!O27*ABS(COS(2*PI()*(SQRT('Link Budget'!O24^2+(2*B$4)^2)-'Link Budget'!O24)/'Link Budget'!O13)))+'Link Budget'!O34+'Link Budget'!O35+'Link Budget'!O36+'Link Budget'!O40+'Link Budget'!O41-'Link Budget'!O44 | C15: ='Link Budget'!O20+20*LOG10('Link Budget'!O13/(4*PI()*'Link Budget'!O24))+10*LOG10(1+'Link Budget'!O27^2-2*'Link Budget'!O27*ABS(COS(2*PI()*(SQRT('Link Budget'!O24^2+(2*C$4)^2)-'Link Budget'!O24)/'Link Budget'!O13)))+'Link Budget'!O34+'Link Budget'!O35+'Link Budget'!O36+'Link Budget'!O40+'Link Budget'!O41-'Link Budget'!O44 | D15: ='Link Budget'!O20+20*LOG10('Link Budget'!O13/(4*PI()*'Link Budget'!O24))+10*LOG10(1+'Link Budget'!O27^2-2*'Link Budget'!O27*ABS(COS(2*PI()*(SQRT('Link Budget'!O24^2+(2*D$4)^2)-'Link Budget'!O24)/'Link Budget'!O13)))+'Link Budget'!O34+'Link Budget'!O35+'Link Budget'!O36+'Link Budget'!O40+'Link Budget'!O41-'Link Budget'!O44 | E15: ='Link Budget'!O20+20*LOG10('Link Budget'!O13/(4*PI()*'Link Budget'!O24))+10*LOG10(1+'Link Budget'!O27^2-2*'Link Budget'!O27*ABS(COS(2*PI()*(SQRT('Link Budget'!O24^2+(2*E$4)^2)-'Link Budget'!O24)/'Link Budget'!O13)))+'Link Budget'!O34+'Link Budget'!O35+'Link Budget'!O36+'Link Budget'!O40+'Link Budget'!O41-'Link Budget'!O44 | F15: ='Link Budget'!O20+20*LOG10('Link Budget'!O13/(4*PI()*'Link Budget'!O24))+10*LOG10(1+'Link Budget'!O27^2-2*'Link Budget'!O27*ABS(COS(2*PI()*(SQRT('Link Budget'!O24^2+(2*F$4)^2)-'Link Budget'!O24)/'Link Budget'!O13)))+'Link Budget'!O34+'Link Budget'!O35+'Link Budget'!O36+'Link Budget'!O40+'Link Budget'!O41-'Link Budget'!O44
A16: ="S12 "&'Link Budget'!P5&" | "&'Link Budget'!P6 | B16: ='Link Budget'!P20+20*LOG10('Link Budget'!P13/(4*PI()*'Link Budget'!P24))+10*LOG10(1+'Link Budget'!P27^2-2*'Link Budget'!P27*ABS(COS(2*PI()*(SQRT('Link Budget'!P24^2+(2*B$4)^2)-'Link Budget'!P24)/'Link Budget'!P13)))+'Link Budget'!P34+'Link Budget'!P35+'Link Budget'!P36+'Link Budget'!P40+'Link Budget'!P41-'Link Budget'!P44 | C16: ='Link Budget'!P20+20*LOG10('Link Budget'!P13/(4*PI()*'Link Budget'!P24))+10*LOG10(1+'Link Budget'!P27^2-2*'Link Budget'!P27*ABS(COS(2*PI()*(SQRT('Link Budget'!P24^2+(2*C$4)^2)-'Link Budget'!P24)/'Link Budget'!P13)))+'Link Budget'!P34+'Link Budget'!P35+'Link Budget'!P36+'Link Budget'!P40+'Link Budget'!P41-'Link Budget'!P44 | D16: ='Link Budget'!P20+20*LOG10('Link Budget'!P13/(4*PI()*'Link Budget'!P24))+10*LOG10(1+'Link Budget'!P27^2-2*'Link Budget'!P27*ABS(COS(2*PI()*(SQRT('Link Budget'!P24^2+(2*D$4)^2)-'Link Budget'!P24)/'Link Budget'!P13)))+'Link Budget'!P34+'Link Budget'!P35+'Link Budget'!P36+'Link Budget'!P40+'Link Budget'!P41-'Link Budget'!P44 | E16: ='Link Budget'!P20+20*LOG10('Link Budget'!P13/(4*PI()*'Link Budget'!P24))+10*LOG10(1+'Link Budget'!P27^2-2*'Link Budget'!P27*ABS(COS(2*PI()*(SQRT('Link Budget'!P24^2+(2*E$4)^2)-'Link Budget'!P24)/'Link Budget'!P13)))+'Link Budget'!P34+'Link Budget'!P35+'Link Budget'!P36+'Link Budget'!P40+'Link Budget'!P41-'Link Budget'!P44 | F16: ='Link Budget'!P20+20*LOG10('Link Budget'!P13/(4*PI()*'Link Budget'!P24))+10*LOG10(1+'Link Budget'!P27^2-2*'Link Budget'!P27*ABS(COS(2*PI()*(SQRT('Link Budget'!P24^2+(2*F$4)^2)-'Link Budget'!P24)/'Link Budget'!P13)))+'Link Budget'!P34+'Link Budget'!P35+'Link Budget'!P36+'Link Budget'!P40+'Link Budget'!P41-'Link Budget'!P44
A17: ="S13 "&'Link Budget'!Q5&" | "&'Link Budget'!Q6 | B17: ='Link Budget'!Q20+20*LOG10('Link Budget'!Q13/(4*PI()*'Link Budget'!Q24))+10*LOG10(1+'Link Budget'!Q27^2-2*'Link Budget'!Q27*ABS(COS(2*PI()*(SQRT('Link Budget'!Q24^2+(2*B$4)^2)-'Link Budget'!Q24)/'Link Budget'!Q13)))+'Link Budget'!Q34+'Link Budget'!Q35+'Link Budget'!Q36+'Link Budget'!Q40+'Link Budget'!Q41-'Link Budget'!Q44 | C17: ='Link Budget'!Q20+20*LOG10('Link Budget'!Q13/(4*PI()*'Link Budget'!Q24))+10*LOG10(1+'Link Budget'!Q27^2-2*'Link Budget'!Q27*ABS(COS(2*PI()*(SQRT('Link Budget'!Q24^2+(2*C$4)^2)-'Link Budget'!Q24)/'Link Budget'!Q13)))+'Link Budget'!Q34+'Link Budget'!Q35+'Link Budget'!Q36+'Link Budget'!Q40+'Link Budget'!Q41-'Link Budget'!Q44 | D17: ='Link Budget'!Q20+20*LOG10('Link Budget'!Q13/(4*PI()*'Link Budget'!Q24))+10*LOG10(1+'Link Budget'!Q27^2-2*'Link Budget'!Q27*ABS(COS(2*PI()*(SQRT('Link Budget'!Q24^2+(2*D$4)^2)-'Link Budget'!Q24)/'Link Budget'!Q13)))+'Link Budget'!Q34+'Link Budget'!Q35+'Link Budget'!Q36+'Link Budget'!Q40+'Link Budget'!Q41-'Link Budget'!Q44 | E17: ='Link Budget'!Q20+20*LOG10('Link Budget'!Q13/(4*PI()*'Link Budget'!Q24))+10*LOG10(1+'Link Budget'!Q27^2-2*'Link Budget'!Q27*ABS(COS(2*PI()*(SQRT('Link Budget'!Q24^2+(2*E$4)^2)-'Link Budget'!Q24)/'Link Budget'!Q13)))+'Link Budget'!Q34+'Link Budget'!Q35+'Link Budget'!Q36+'Link Budget'!Q40+'Link Budget'!Q41-'Link Budget'!Q44 | F17: ='Link Budget'!Q20+20*LOG10('Link Budget'!Q13/(4*PI()*'Link Budget'!Q24))+10*LOG10(1+'Link Budget'!Q27^2-2*'Link Budget'!Q27*ABS(COS(2*PI()*(SQRT('Link Budget'!Q24^2+(2*F$4)^2)-'Link Budget'!Q24)/'Link Budget'!Q13)))+'Link Budget'!Q34+'Link Budget'!Q35+'Link Budget'!Q36+'Link Budget'!Q40+'Link Budget'!Q41-'Link Budget'!Q44
A18: ="S14 "&'Link Budget'!R5&" | "&'Link Budget'!R6 | B18: ='Link Budget'!R20+20*LOG10('Link Budget'!R13/(4*PI()*'Link Budget'!R24))+10*LOG10(1+'Link Budget'!R27^2-2*'Link Budget'!R27*ABS(COS(2*PI()*(SQRT('Link Budget'!R24^2+(2*B$4)^2)-'Link Budget'!R24)/'Link Budget'!R13)))+'Link Budget'!R34+'Link Budget'!R35+'Link Budget'!R36+'Link Budget'!R40+'Link Budget'!R41-'Link Budget'!R44 | C18: ='Link Budget'!R20+20*LOG10('Link Budget'!R13/(4*PI()*'Link Budget'!R24))+10*LOG10(1+'Link Budget'!R27^2-2*'Link Budget'!R27*ABS(COS(2*PI()*(SQRT('Link Budget'!R24^2+(2*C$4)^2)-'Link Budget'!R24)/'Link Budget'!R13)))+'Link Budget'!R34+'Link Budget'!R35+'Link Budget'!R36+'Link Budget'!R40+'Link Budget'!R41-'Link Budget'!R44 | D18: ='Link Budget'!R20+20*LOG10('Link Budget'!R13/(4*PI()*'Link Budget'!R24))+10*LOG10(1+'Link Budget'!R27^2-2*'Link Budget'!R27*ABS(COS(2*PI()*(SQRT('Link Budget'!R24^2+(2*D$4)^2)-'Link Budget'!R24)/'Link Budget'!R13)))+'Link Budget'!R34+'Link Budget'!R35+'Link Budget'!R36+'Link Budget'!R40+'Link Budget'!R41-'Link Budget'!R44 | E18: ='Link Budget'!R20+20*LOG10('Link Budget'!R13/(4*PI()*'Link Budget'!R24))+10*LOG10(1+'Link Budget'!R27^2-2*'Link Budget'!R27*ABS(COS(2*PI()*(SQRT('Link Budget'!R24^2+(2*E$4)^2)-'Link Budget'!R24)/'Link Budget'!R13)))+'Link Budget'!R34+'Link Budget'!R35+'Link Budget'!R36+'Link Budget'!R40+'Link Budget'!R41-'Link Budget'!R44 | F18: ='Link Budget'!R20+20*LOG10('Link Budget'!R13/(4*PI()*'Link Budget'!R24))+10*LOG10(1+'Link Budget'!R27^2-2*'Link Budget'!R27*ABS(COS(2*PI()*(SQRT('Link Budget'!R24^2+(2*F$4)^2)-'Link Budget'!R24)/'Link Budget'!R13)))+'Link Budget'!R34+'Link Budget'!R35+'Link Budget'!R36+'Link Budget'!R40+'Link Budget'!R41-'Link Budget'!R44
A19: ="S15 "&'Link Budget'!S5&" | "&'Link Budget'!S6 | B19: ='Link Budget'!S20+20*LOG10('Link Budget'!S13/(4*PI()*'Link Budget'!S24))+10*LOG10(1+'Link Budget'!S27^2-2*'Link Budget'!S27*ABS(COS(2*PI()*(SQRT('Link Budget'!S24^2+(2*B$4)^2)-'Link Budget'!S24)/'Link Budget'!S13)))+'Link Budget'!S34+'Link Budget'!S35+'Link Budget'!S36+'Link Budget'!S40+'Link Budget'!S41-'Link Budget'!S44 | C19: ='Link Budget'!S20+20*LOG10('Link Budget'!S13/(4*PI()*'Link Budget'!S24))+10*LOG10(1+'Link Budget'!S27^2-2*'Link Budget'!S27*ABS(COS(2*PI()*(SQRT('Link Budget'!S24^2+(2*C$4)^2)-'Link Budget'!S24)/'Link Budget'!S13)))+'Link Budget'!S34+'Link Budget'!S35+'Link Budget'!S36+'Link Budget'!S40+'Link Budget'!S41-'Link Budget'!S44 | D19: ='Link Budget'!S20+20*LOG10('Link Budget'!S13/(4*PI()*'Link Budget'!S24))+10*LOG10(1+'Link Budget'!S27^2-2*'Link Budget'!S27*ABS(COS(2*PI()*(SQRT('Link Budget'!S24^2+(2*D$4)^2)-'Link Budget'!S24)/'Link Budget'!S13)))+'Link Budget'!S34+'Link Budget'!S35+'Link Budget'!S36+'Link Budget'!S40+'Link Budget'!S41-'Link Budget'!S44 | E19: ='Link Budget'!S20+20*LOG10('Link Budget'!S13/(4*PI()*'Link Budget'!S24))+10*LOG10(1+'Link Budget'!S27^2-2*'Link Budget'!S27*ABS(COS(2*PI()*(SQRT('Link Budget'!S24^2+(2*E$4)^2)-'Link Budget'!S24)/'Link Budget'!S13)))+'Link Budget'!S34+'Link Budget'!S35+'Link Budget'!S36+'Link Budget'!S40+'Link Budget'!S41-'Link Budget'!S44 | F19: ='Link Budget'!S20+20*LOG10('Link Budget'!S13/(4*PI()*'Link Budget'!S24))+10*LOG10(1+'Link Budget'!S27^2-2*'Link Budget'!S27*ABS(COS(2*PI()*(SQRT('Link Budget'!S24^2+(2*F$4)^2)-'Link Budget'!S24)/'Link Budget'!S13)))+'Link Budget'!S34+'Link Budget'!S35+'Link Budget'!S36+'Link Budget'!S40+'Link Budget'!S41-'Link Budget'!S44

Sheet Throughput
A1: How many lines arrive in one round? (selective-repeat ARQ, block ACK)
A3: File size | B3: 1000000 | C3: B | D3: RULE: about 1 MB
A4: Lines in file | B4: 10000 | C4: lines | D4: RULE: about 10 000 equal-length lines
A5: Round duration | B5: 120 | C5: s | D5: RULE: 2 minutes (SRI, MRM)
A6: Compression ratio (planning) | B6: 2 | C6: x | D6: ASSUMPTION: measure on sample text; 1.0 = none
A7: Usable bandwidth at 869.40-869.65 MHz | B7: 250 | C7: kHz | D7: RULE (CNAF UN-39): whole 250 kHz may be one high-speed channel
A9: Bytes per line | B9: =B3/B4
A10: Goodput needed for the whole file, no compression | B10: =B3*8/B5/1000 | C10: kbps
A11: Goodput needed for the whole file, with planning compression | B11: =B10/B6 | C11: kbps
A13: Configuration | B13: Air rate (kbps) | C13: Payload (B) | D13: Frame overhead (B) | E13: Frames per ACK | F13: ACK frame (B) | G13: Turnaround (ms) | H13: System efficiency | I13: Mod. index h | J13: Frame time (ms) | K13: Cycle time (ms) | L13: Goodput (kbps) | M13: Lines, no compression | N13: Lines, planning compression | O13: Occupied BW est. (kHz) | P13: Fits 250 kHz sub-band?
A14: 868 FSK radio @38.4 kbps | B14: 38.4 | C14: 60 | D14: 13 | E14: 16 | F14: 20 | G14: 1 | H14: 0.85 | I14: 1 | J14: =(C14+D14)*8/B14 | K14: =E14*J14+F14*8/B14+2*G14 | L14: =E14*C14*8/K14*H14 | M14: =MIN($B$4,INT(L14*1000*$B$5/8/$B$9)) | N14: =MIN($B$4,INT(L14*1000*$B$5/8*$B$6/$B$9)) | O14: =B14*(1+I14) | P14: =IF(O14<=$B$7,"yes","NO")
A15: 868 FSK radio @100 kbps | B15: 100 | C15: 60 | D15: 13 | E15: 16 | F15: 20 | G15: 1 | H15: 0.85 | I15: 1 | J15: =(C15+D15)*8/B15 | K15: =E15*J15+F15*8/B15+2*G15 | L15: =E15*C15*8/K15*H15 | M15: =MIN($B$4,INT(L15*1000*$B$5/8/$B$9)) | N15: =MIN($B$4,INT(L15*1000*$B$5/8*$B$6/$B$9)) | O15: =B15*(1+I15) | P15: =IF(O15<=$B$7,"yes","NO")
A16: 868 GFSK radio @150 kbps, h=0.5 | B16: 150 | C16: 60 | D16: 13 | E16: 16 | F16: 20 | G16: 1 | H16: 0.85 | I16: 0.5 | J16: =(C16+D16)*8/B16 | K16: =E16*J16+F16*8/B16+2*G16 | L16: =E16*C16*8/K16*H16 | M16: =MIN($B$4,INT(L16*1000*$B$5/8/$B$9)) | N16: =MIN($B$4,INT(L16*1000*$B$5/8*$B$6/$B$9)) | O16: =B16*(1+I16) | P16: =IF(O16<=$B$7,"yes","NO")
A17: 868 MRM shared: 5 ch x 50 kHz @19.2 kbps | B17: 19.2 | C17: 60 | D17: 13 | E17: 16 | F17: 20 | G17: 1 | H17: 0.85 | I17: 1 | J17: =(C17+D17)*8/B17 | K17: =E17*J17+F17*8/B17+2*G17 | L17: =E17*C17*8/K17*H17 | M17: =MIN($B$4,INT(L17*1000*$B$5/8/$B$9)) | N17: =MIN($B$4,INT(L17*1000*$B$5/8*$B$6/$B$9)) | O17: =B17*(1+I17) | P17: =IF(O17<=$B$7,"yes","NO")
A18: nRF24 2.4 GHz @250 kbps | B18: 250 | C18: 32 | D18: 9.125 | E18: 16 | F18: 12 | G18: 0.25 | H18: 0.85 | J18: =(C18+D18)*8/B18 | K18: =E18*J18+F18*8/B18+2*G18 | L18: =E18*C18*8/K18*H18 | M18: =MIN($B$4,INT(L18*1000*$B$5/8/$B$9)) | N18: =MIN($B$4,INT(L18*1000*$B$5/8*$B$6/$B$9)) | O18: ~1000-2000 (2.4 GHz, n/a) | P18: n/a
A19: nRF24 2.4 GHz @1 Mbps | B19: 1000 | C19: 32 | D19: 9.125 | E19: 16 | F19: 12 | G19: 0.25 | H19: 0.85 | J19: =(C19+D19)*8/B19 | K19: =E19*J19+F19*8/B19+2*G19 | L19: =E19*C19*8/K19*H19 | M19: =MIN($B$4,INT(L19*1000*$B$5/8/$B$9)) | N19: =MIN($B$4,INT(L19*1000*$B$5/8*$B$6/$B$9)) | O19: ~1000-2000 (2.4 GHz, n/a) | P19: n/a
A20: nRF24 2.4 GHz @2 Mbps | B20: 2000 | C20: 32 | D20: 9.125 | E20: 16 | F20: 12 | G20: 0.25 | H20: 0.85 | J20: =(C20+D20)*8/B20 | K20: =E20*J20+F20*8/B20+2*G20 | L20: =E20*C20*8/K20*H20 | M20: =MIN($B$4,INT(L20*1000*$B$5/8/$B$9)) | N20: =MIN($B$4,INT(L20*1000*$B$5/8*$B$6/$B$9)) | O20: ~1000-2000 (2.4 GHz, n/a) | P20: n/a
A22: Notes: overhead = preamble + sync + length + 4 B header + CRC-16 (sub-GHz) or nRF24 Enhanced ShockBurst fields (1 B preamble, 5 B address, 9-bit PCF, 2 B CRC). Turnaround = radio TX/RX switch + MCU handling [ASSUMPTION]. System efficiency covers SPI/FIFO service and USB writes [ASSUMPTION]. Occupied bandwidth uses Carson's rule 2Δf + Rb with Δf = h·Rb/2 (an estimate; verify on the spectrum analyser, test T13). The MRM-shared row shows what 868 MHz gives if all teams split 869.4-869.65 MHz.

Sheet Candidates
A1: Radio module shortlist - datasheet values (verified 2026-10-03) and compliance notes
A3: Module / chip | B3: Band(s) | C3: Max TX power | D3: TX current @max | E3: RX current | F3: Sensitivity (datasheet) | G3: Max data rate | H3: Limits / gotchas | I3: Rule compliance (standard-protocol ban) | J3: Fits our use | K3: Unit price | L3: Source
A4: HopeRF RFM69HCW (Semtech SX1231H), 868 MHz variant | B4: 433 / 868 / 915 MHz variants | C4: +20 dBm (PA_BOOST); +17 dBm without high-power mode | D4: 130 mA @+20; 95 mA @+17 | E4: 16 mA | F4: -118 dBm @1.2 kbps; -114 @4.8 kbps; -105 @38.4 kbps (FDA 40 kHz). No figure above 38.4 kbps. | G4: 300 kbps FSK | H4: +20 dBm limited to 1 % duty cycle (datasheet §3.3.7) -> use +17 dBm for 2-min rounds. 66 B FIFO. No SAW filter. | I4: Proprietary FSK packet radio - LOW risk; confirm on Atenea | J4: SRI/NM/MRM at 868; huge libraries (RadioHead, LowPowerLab) | K4: TO VERIFY (ET to quote Mouser/DigiKey/LCSC) | L4: HopeRF RFM69HCW datasheet v1.1, Tables 2/4/6 and §3.3.7 - https://cdn-shop.adafruit.com/product-files/3076/RFM69HCW-V1.1.pdf
A5: Si4463 modules (e.g. HopeRF RFM26W, NiceRF/Ebyte boards) | B5: 142-1050 MHz | C5: +20 dBm | D5: 85 mA @+20 dBm, 868 MHz | E5: ~10-14 mA (datasheet) | F5: 868/915: -109 dBm @40 kbps; -104 @100 kbps; -97 @500 kbps (GFSK, BER 0.1 %); -88 @1 Mbps 4GFSK | G5: 500 kbps (G)FSK; 1 Mbps 4GFSK | H5: Best sensitivity + power of the group; no duty-cycle note found. Config via WDS-generated register sets (steeper learning curve). | I5: Proprietary radio, but the datasheet advertises IEEE 802.15.4g PHY support -> LOW-MEDIUM risk; ask Atenea | J5: Strongest 868 option for MRM margin | K5: TO VERIFY | L5: Silicon Labs Si4463/61/60-C datasheet Rev 1.0, Table 3 (RX 915/868 MHz) - https://datasheet.octopart.com/SI4463-C2A-GM-Silicon-Labs-datasheet-78834891.pdf
A6: TI CC1101 modules (e.g. Ebyte E07-M1101D) | B6: 300-348 / 387-464 / 779-928 MHz | C6: +12 dBm @868 | D6: 34 mA @+12 dBm | E6: ~15-17 mA | F6: 868: -112 dBm @1.2 kBaud; -104 @38.4; -95 @250 (540 kHz filter); -90 @500 kBaud MSK | G6: 500 kBaud (600 kbps 4-FSK) | H6: Lowest power of the 868 options. 250 kBaud setting needs 540 kHz filter -> does NOT fit the 250 kHz sub-band; practical ceiling ~100 kbps there. | I6: Proprietary - LOW risk | J6: Fine for SRI; thinner MRM margin | K6: TO VERIFY | L6: TI CC1101 datasheet SWRS061I, Tables 4/7 (868/915 MHz) - https://www.ti.com/lit/ds/symlink/cc1101.pdf
A7: Nordic nRF24L01+ (and PA/LNA variants) | B7: 2.400-2.525 GHz | C7: 0 dBm (PA/LNA modules: more, but must be backed off to <=10 dBm e.i.r.p.) | D7: 11.3 mA @0 dBm | E7: ~12-14 mA | F7: -82 dBm @2 Mbps; -85 @1 Mbps; -94 @250 kbps (BER 0.1 %) | G7: 2 Mbps | H7: 32 B max payload; auto-ACK/retransmit in hardware (Enhanced ShockBurst). Many clones on the market - buy from a distributor. | I7: Enhanced ShockBurst is Nordic-proprietary - LOW-MEDIUM risk; confirm on Atenea | J7: Speed for SRI; weak margin at 260 m | K7: TO VERIFY | L7: Nordic nRF24L01+ Product Specification v1.0, Tables 7 and 17 - https://www.sparkfun.com/datasheets/Components/SMD/nRF24L01Pluss_Preliminary_Product_Specification_v1_0.pdf
A8: TI CC2500 | B8: 2.400-2.4835 GHz | C8: +1 dBm | D8: 21.5 mA @+1 dBm | E8: ~13-17 mA | F8: -104 dBm @2.4 kBaud; -99 @10 kBaud; -89 @250 kBaud; -83 @500 kBaud | G8: 500 kBaud | H8: Similar class to nRF24 with more modulation control. | I8: Proprietary - LOW risk | J8: Alternative 2.4 GHz option | K8: TO VERIFY | L8: TI CC2500 datasheet, RF receive section - https://www.ti.com/lit/ds/symlink/cc2500.pdf
A9: EXCLUDE: LoRa chips (SX127x/RFM95, SX126x, SX1280, LLCC68) | B9: 433/868/2.4 GHz | I9: LoRa is named as banned on the Session 1 spec slide; even FSK-only use of a LoRa chip is a compliance risk | J9: Do not buy | L9: Session #1 slide 'Transceiver Specs (I)'
A10: EXCLUDE: radio SoCs (CC1310/CC1312, nRF52, ESP32, STM32WL...) | I10: Contain a microprocessor (second micro module) and/or BLE/ZigBee/LoRa stacks | J10: Do not buy | L10: Rules PDF: 'one but only one module including a microprocessor'; standard-protocol ban
A11: EXCLUDE: 915 MHz (US) module variants | B11: 902-928 MHz | I11: 915-921 MHz is mobile/GSM-R spectrum in Spain (CNAF UN-40), not SRD | J11: Buy 868 variants only | L11: CNAF 2017 (Orden ETU/1033/2017), notas UN - https://www.boe.es/buscar/doc.php?id=BOE-A-2017-12318

Sheet Regulatory
A1: Usable unlicensed bands for a 2-minute continuous round (CNAF 2017 notas UN, as the rules require)
A2: Text checked on 2026-10-03 against the BOE publication of CNAF 2017 and the current CNAF 2021; the limits below are identical in both. Duty cycle is assessed over a 1-hour window (ERC/REC 70-03).
A4: Band | B4: CNAF note | C4: Max power | D4: Access condition | E4: 2-min continuous TX OK? | F4: Width | G4: Comment
A5: 433.050-434.790 MHz | B5: UN-30 | C5: 1 mW e.r.p. (-13 dBm/10 kHz) | D5: none | E5: Yes, but 1 mW | F5: 1.74 MHz | G5: Too weak.
A6: 433.050-434.040 MHz | B6: UN-30 | C6: 10 mW e.r.p. | D6: duty cycle <= 10 % | E6: Yes (120 s < 360 s/h) | F6: 0.99 MHz | G6: λ/4 = 17 cm: does not fit the 15x15x7 cm box without heavy shortening.
A7: 868.000-868.600 MHz | B7: UN-39 | C7: 25 mW e.r.p. | D7: LBT+AFA (EN 300 220) or duty cycle <= 1 % | E7: No (1 % = 36 s/h) | F7: 600 kHz
A8: 868.700-869.200 MHz | B8: UN-39 | C8: 25 mW e.r.p. | D8: LBT+AFA or duty cycle <= 0.1 % | E8: No | F8: 500 kHz
A9: 869.400-869.650 MHz | B9: UN-39 | C9: 500 mW e.r.p. | D9: LBT+AFA or duty cycle <= 10 % | E9: YES (120 s < 360 s/h) | F9: 250 kHz | G9: THE 868 option. 25 kHz channelisation, but the whole band may be one high-speed data channel. One 120 s SRI + one 120 s MRM = 240 s/h for the TX device: compliant.
A10: 869.700-870.000 MHz | B10: UN-39 | C10: 5 mW e.r.p. (no DC) / 25 mW (DC <= 1 %) | E10: 5 mW only | F10: 300 kHz | G10: Low power.
A11: 2400-2483.5 MHz | B11: UN-85 b) | C11: 10 mW e.i.r.p. | D11: none (generic SRD, EN 300 440) | E11: YES | F11: 83.5 MHz | G11: Room for every team on its own channel (MRM). Campus WiFi/BT share the band.
A12: 2400-2483.5 MHz | B12: UN-85 a) | C12: 100 mW e.i.r.p.; 100 mW/100 kHz FHSS, 10 mW/MHz other | D12: mitigation techniques (EN 300 328) mandatory | E12: Yes, if mitigation implemented | F12: 83.5 MHz | G12: Wideband data/RLAN class. Whether a student FHSS/LBT design qualifies is a question for Atenea.
A13: 5725-5875 MHz | B13: UN-130 | C13: 25 mW e.i.r.p. | D13: none (generic SRD, EN 300 440) | E13: Yes | F13: 150 MHz | G13: Few cheap non-WiFi modules; higher path loss and container loss. Not shortlisted.
A15: Sources
A16: CNAF 2017 (Orden ETU/1033/2017), notas UN - https://www.boe.es/buscar/doc.php?id=BOE-A-2017-12318
A17: CNAF 2021 (Orden ETD/1449/2021), notas UN - https://www.boe.es/diario_boe/txt.php?id=BOE-A-2021-21346
A18: Rules PDF: 'The system will need to be compliant with limitations according to CNAF 2017 rules (Notas UN CNAF 2017)'
